Workbook

Sheet 📋 Devis Client
E4: DEVIS DE TRANSPORT
E6: Transport · Livraison · Suivi Digital
B12: N° DEVIS : | C12: ="OW-"&TEXT('⚙️ Paramètres'!C9,"0000")&"-"&TEXT(TODAY(),"MMYYYY") -> OW-0001-06YYYY | E12: DATE : | F12: =TODAY() -> 46203 | G12: VALIDE JUSQU'AU : | H12: =TODAY()+'⚙️ Paramètres'!C13 -> 46233
B14: 👤 INFORMATIONS CLIENT | F14: 🚛 ONE WAY — TRANSPORT
B15: Nom / Société : | C15: Nom du client | F15: Société : | G15: One Way SARL
B16: Adresse : | C16: Adresse complète | F16: Adresse : | G16: Antananarivo, Madagascar
B17: Ville : | C17: Antananarivo | F17: Téléphone : | G17: +261 XX XXX XX XX
B18: Téléphone : | C18: +261 XX XXX XX XX | F18: Email : | G18: contact@oneway.mg
B19: Email : | C19: client@email.mg | F19: MVola : | G19: 0XX XX XXX XX
B20: N° Client : | C20: OW-CLI-001 | F20: NIF / STAT : | G20: XXX XXX XXX
B22: 📍 PARAMÈTRES DU TRANSPORT
B23: Point de chargement : | C23: Antananarivo | F23: Point de livraison : | G23: Toamasina
B24: Distance estimée (km) : | C24: 357 | F24: Trajet : | G24: Aller-retour
B25: Type de véhicule : | C25: Camion 5 tonnes | F25: Type de marchandise : | G25: Générale
B26: Date de transport : | C26: — | F26: Durée estimée : | G26: 5h30 (aller)
B27: Type de route : | C27: Route nationale | F27: Conditions particulières : | G27: —
B29: 📦 DÉTAIL DES PRESTATIONS
B30: N° | C30: DÉSIGNATION / DESCRIPTION | E30: TYPE | F30: QTÉ | G30: UNITÉ | H30: P.U. (Ar) | I30: TOTAL (Ar)
B31: 1 | C31: Transport marchandises — aller (chargé), tarif km | E31: Transport | F31: 357 | G31: km | H31: 2800 | I31: =F31*H31 -> 999600
B32: =B31+1 -> 2 | C32: Carburant aller-retour | E32: Carburant | F32: 89 | G32: litre | H32: ='⚙️ Paramètres'!C18 -> 4900 | I32: =F32*H32 -> 436100
B33: =B32+1 -> 3 | C33: Retour véhicule à vide (repositionnement) | E33: Aller-retour | F33: 1 | G33: forfait | H33: =ROUND((I31+I32)*'⚙️ Paramètres'!C15,0) -> 1004990 | I33: =F33*H33 -> 1004990
B34: =B33+1 -> 4 | C34: Forfait prise en charge / frais fixes de base | E34: Transport | F34: 1 | G34: forfait | H34: 100000 | I34: =F34*H34 -> 100000
B35: =B34+1 -> 5 | C35: Majoration type de marchandise (coefficient) | E35: Supplément | F35: 0 | G35: forfait | H35: 0 | I35: =F35*H35 -> 0
B36: =B35+1 -> 6 | C36: Manutention au chargement | E36: Main d'œuvre | F36: 1 | G36: forfait | H36: 15000 | I36: =F36*H36 -> 15000
B37: =B36+1 -> 7 | C37: Manutention au déchargement | E37: Main d'œuvre | F37: 1 | G37: forfait | H37: 15000 | I37: =F37*H37 -> 15000
B38: =B37+1 -> 8 | C38: Arrimage / sanglage / bâchage | E38: Sécurité | F38: 1 | G38: forfait | H38: 25000 | I38: =F38*H38 -> 25000
B39: =B38+1 -> 9 | C39: Assurance marchandise (% valeur déclarée) | E39: Assurance | F39: 0 | G39: % valeur | H39: 0 | I39: =F39*H39 -> 0
B40: =B39+1 -> 10 | C40: Gardiennage / stationnement de nuit | E40: Sécurité | F40: 0 | G40: nuit | H40: 30000 | I40: =F40*H40 -> 0
B41: =B40+1 -> 11 | C41: Supplément frigorifique (groupe froid / jour) | E41: Supplément | F41: 0 | G41: jour | H41: 60000 | I41: =F41*H41 -> 0
B42: =B41+1 -> 12 | C42: Frais administratifs / documentation | E42: Administratif | F42: 0 | G42: dossier | H42: 15000 | I42: =F42*H42 -> 0
B43: =B42+1 -> 13 | C43: Ristournes / frais de barrière communale | E43: Administratif | F43: 0 | G43: forfait | H43: 25000 | I43: =F43*H43 -> 0
B44: =B43+1 -> 14 | C44: Emballage / palettisation / film étirable | E44: Conditionnement | F44: 0 | G44: forfait | H44: 20000 | I44: =F44*H44 -> 0
B45: =B44+1 -> 15 | C45: Stockage / entreposage temporaire | E45: Logistique | F45: 0 | G45: jour | H45: 20000 | I45: =F45*H45 -> 0
... B48: =B47+1 -> 18 | C48: Supplément saison des pluies / piste dégradée | E48: Supplément | F48: 0 | G48: forfait | H48: 200000 | I48: =F48*H48 -> 0
B49: SOUS-TOTAL H.T. | G49: =SUM(I31:I48) -> 2595690
B50: Remise commerciale (%) → | F50: 0 | G50: =-ROUND(G49*F50/100,0) -> 0
B51: Base imposable (après remise) | G51: =G49+G50 -> 2595690
B52: TVA (Oui / Non) → | F52: Non | G52: =IF(F52="Oui",ROUND(G51*0.2,0),0) -> 0
B53: 💰 TOTAL À PAYER (TTC) | G53: =G51+G52 -> 2595690
B55: 💳 CONDITIONS DE PAIEMENT
...

Sheet ⚙️ Paramètres
B2: ⚙️ PARAMÈTRES & TARIFS DE RÉFÉRENCE — ONE WAY
B8: 🏢 INFORMATIONS GÉNÉRALES
B9: Numéro séquence devis | C9: 1 | D9: N° | E9: Auto-incrémenté
B10: Remise commerciale défaut | C10: 0 | D10: % | E10: 0 si aucune remise
B11: TVA applicable par défaut | C11: Non | E11: Oui ou Non
B12: Devise | C12: Ariary (MGA) | E12: Toutes valeurs en Ar
B13: Validité du devis | C13: 30 | D13: jours | E13: Délai d'engagement du prix
B14: Trajet par défaut | C14: Aller-retour | E14: Le véhicule revient
B15: Coefficient retour à vide | C15: 0.7 | D15: × | E15: 0 = aller simple · 1 = retour plein
B17: ⛽ PRIX DU CARBURANT (modifiable selon le cours)
B18: Gasoil (diesel) | C18: 4900 | D18: / litre | E18: Tous les frais de carburant se recalculent à partir de cette valeur.
B19: Essence (sans plomb) | C19: 5100 | D19: / litre | E19: Tous les frais de carburant se recalculent à partir de cette valeur.
B21: 🛣️ GRILLE TARIFAIRE KILOMÉTRIQUE (tarif km HORS carburant + carburant par type)
B22: TYPE DE VÉHICULE | C22: CAPACITÉ | D22: TARIF/km (hors carburant) | E22: CONSO (L/100km) | F22: CARBURANT/km | G22: FORFAIT BASE | H22: MAJORATION
B23: 🛵 Moto-taxi / Tricycle | C23: < 200 kg | D23: 800 | E23: 3 | F23: =ROUND(E23*$C$19/100,0) -> 153 | G23: 15000 | H23: 0
B24: 🚐 Camionnette légère | C24: 200 – 800 kg | D24: 1200 | E24: 10 | F24: =ROUND(E24*$C$18/100,0) -> 490 | G24: 30000 | H24: 0.1
B25: 🚚 Camion 3 tonnes | C25: 800 kg – 3 T | D25: 1900 | E25: 18 | F25: =ROUND(E25*$C$18/100,0) -> 882 | G25: 60000 | H25: 0.15
B26: 🚚 Camion 5 tonnes | C26: 3 T – 5 T | D26: 2800 | E26: 25 | F26: =ROUND(E26*$C$18/100,0) -> 1225 | G26: 100000 | H26: 0.2
B27: 🚛 Camion 10 tonnes | C27: 5 T – 10 T | D27: 3900 | E27: 32 | F27: =ROUND(E27*$C$18/100,0) -> 1568 | G27: 180000 | H27: 0.25
B28: 🚛 Semi-remorque 20 T | C28: 10 T – 20 T | D28: 5600 | E28: 38 | F28: =ROUND(E28*$C$18/100,0) -> 1862 | G28: 300000 | H28: 0.3
B29: ❄️ Camion frigorifique 5 T | C29: 3 T – 5 T frigo | D29: 3800 | E29: 28 | F29: =ROUND(E29*$C$18/100,0) -> 1372 | G29: 150000 | H29: 0.2
B30: 🚜 Camion benne | C30: Jusqu'à 15 T | D30: 4300 | E30: 35 | F30: =ROUND(E30*$C$18/100,0) -> 1715 | G30: 200000 | H30: 0.25
B31: 📦 Conteneur 20 pieds | C31: Max 24 T | D31: 4600 | E31: 38 | F31: =ROUND(E31*$C$18/100,0) -> 1862 | G31: 250000 | H31: 0.35
B32: 📦 Conteneur 40 pieds | C32: Max 28 T | D32: 6300 | E32: 45 | F32: =ROUND(E32*$C$18/100,0) -> 2205 | G32: 400000 | H32: 0.4
B34: 🗺️ ROUTES PRINCIPALES MADAGASCAR (ALLER-RETOUR, général, carburant inclus)
B35: ROUTE | C35: DISTANCE | D35: CAMION 3T | E35: CAMION 5T | F35: SEMI-REM. 20T | G35: DURÉE MOY.
B36: Antananarivo → Toamasina | C36: 357 km | D36: 1921000 | E36: 2883000 | F36: 5848000 | G36: 5h30
B37: Antananarivo → Antsirabe | C37: 167 km | D37: 931000 | E37: 1402000 | F37: 2895000 | G37: 3h00
B38: Antananarivo → Mahajanga | C38: 472 km | D38: 2521000 | E38: 3779000 | F38: 7636000 | G38: 8h00
B39: Antananarivo → Fianarantsoa | C39: 404 km | D39: 2166000 | E39: 3249000 | F39: 6579000 | G39: 7h00
B40: Antananarivo → Toliara | C40: 756 km | D40: 4002000 | E40: 5993000 | F40: 12049000 | G40: 13h00
B41: Antananarivo → Ambositra | C41: 258 km | D41: 1405000 | E41: 2111000 | F41: 4310000 | G41: 4h30
B42: Antananarivo → Moramanga | C42: 109 km | D42: 628000 | E42: 950000 | F42: 1994000 | G42: 2h00
B43: Antananarivo → Antalaha | C43: 820 km | D43: 4335000 | E43: 6491000 | F43: 13044000 | G43: 15h00
B44: Antananarivo → Fort-Dauphin | C44: 950 km | D44: 5013000 | E44: 7505000 | F44: 15064000 | G44: 18h00
B45: Toamasina → Mahajanga | C45: 720 km | D45: 3814000 | E45: 5712000 | F45: 11490000 | G45: 14h00
B46: Antsirabe → Fianarantsoa | C46: 237 km | D46: 1296000 | E46: 1947000 | F46: 3983000 | G46: 4h30
B47: Mahajanga → Antsiranana | C47: 620 km | D47: 3293000 | E47: 4933000 | F47: 9936000 | G47: 11h30
B49: 📊 COEFFICIENTS DE MAJORATION (marchandise / situation)
B50: TYPE / SITUATION | C50: COEFF. | D50: SURCHARGE | E50: NOTES
...

Sheet 🧮 Calculateur Rapide
B2: 🧮 CALCULATEUR DE PRIX RAPIDE — ONE WAY
B8: 📝 PARAMÈTRES DE LA DEMANDE
B9: Distance du trajet — aller (km) | C9: 357 | D9: km | F9: Véhicule :
B10: Type véhicule (1=Moto → 10=Cont40') | C10: 4 | D10: 1 à 10 | F10: =INDEX('⚙️ Paramètres'!$B$23:$B$32,C10) -> 🚚 Camion 5 tonnes
B11: Poids de la marchandise | C11: 4000 | D11: kg
B12: Valeur déclarée marchandise | C12: 20000000 | D12: Ar
B13: Manutention chargement ? | C13: Oui | D13: Oui/Non
B14: Manutention déchargement ? | C14: Oui | D14: Oui/Non
B15: Aller-retour ? | C15: Oui | D15: Oui/Non
B16: Remise à appliquer | C16: 0 | D16: %
B17: TVA ? | C17: Non | D17: Oui/Non
B19: 💰 RÉSULTAT DU CALCUL AUTOMATIQUE
B20: Frais kilométriques aller (hors carburant) | C20: =ROUND(C9*INDEX('⚙️ Paramètres'!$D$23:$D$32,C10)*(1+INDEX('⚙️ Paramètres'!$H$23:$H$32,C10)),0) -> 1199520
B21: Carburant aller (selon type de véhicule) | C21: =ROUND(C9*INDEX('⚙️ Paramètres'!$F$23:$F$32,C10),0) -> 437325
B22: Retour véhicule à vide (repositionnement) | C22: =IF(C15="Oui",ROUND((C20+C21)*'⚙️ Paramètres'!$C$15,0),0) -> 1145792
B23: Forfait de base véhicule | C23: =INDEX('⚙️ Paramètres'!$G$23:$G$32,C10) -> 100000
B24: Manutention chargement | C24: =IF(C13="Oui",ROUND(INDEX('⚙️ Paramètres'!$G$23:$G$32,C10)*0.15,0),0) -> 15000
B25: Manutention déchargement | C25: =IF(C14="Oui",ROUND(INDEX('⚙️ Paramètres'!$G$23:$G$32,C10)*0.15,0),0) -> 15000
B26: Assurance (0,5% valeur déclarée) | C26: =ROUND(C12*0.005,0) -> 100000
B27: Frais divers (péages, 3% du transport) | C27: =ROUND((C20+C22)*0.03,0) -> 70359
B28: SOUS-TOTAL H.T. | C28: =SUM(C20:C27) -> 3082996
B29: Remise commerciale | C29: =-ROUND(C28*C16/100,0) -> 0
B30: TVA 20% (si applicable) | C30: =IF(C17="Oui",ROUND((C28+C29)*0.2,0),0) -> 0
B31: 💰 TOTAL ESTIMÉ TTC | C31: =C28+C29+C30 -> 3082996
B32: Prix moyen / km (aller) | C32: =IF(C9>0,ROUND(C31/C9,0),0) -> 8636

Sheet 📊 Historique Devis
B2: 📊 HISTORIQUE DES DEVIS — ONE WAY (aller-retour)
B6: N° DEVIS | C6: DATE | D6: CLIENT | E6: DÉPART | F6: ARRIVÉE | G6: DISTANCE | H6: VÉHICULE | I6: HT (Ar) | J6: TTC (Ar) | K6: STATUT | L6: NOTES
B7: OW-0001 | C7: 15/05/2026 | D7: Société ABC Import | E7: Analakely, Tanà | F7: Toamasina Port | G7: 357 km | H7: Camion 5T | I7: 2883000 | J7: 2883000 | K7: ✅ Accepté | L7: Livraison OK
B8: OW-0002 | C8: 18/05/2026 | D8: Marie Rakoto | E8: Ivandry, Tanà | F8: Antsirabe Centre | G8: 167 km | H8: Camionnette | I8: 931000 | J8: 931000 | K8: ✅ Accepté | L8: Marchandises générales
B9: OW-0003 | C9: 20/05/2026 | D9: Export Mada SARL | E9: Tsaralalàna | F9: Mahajanga Port | G9: 472 km | H9: Camion 5T | I9: 3779000 | J9: 3779000 | K9: ✅ Accepté | L9: Périssables urgents
B10: OW-0004 | C10: 21/05/2026 | D10: Fara Rasolofo | E10: 67 Ha, Tanà | F10: Fianarantsoa | G10: 404 km | H10: Semi-remorque | I10: 6579000 | J10: 6579000 | K10: ✅ Accepté | L10: Semi-remorque
B11: OW-0005 | C11: 23/05/2026 | D11: Solo Andria | E11: Ambohimangakely | F11: Moramanga | G11: 109 km | H11: Moto-tricycle | I11: 365000 | J11: 365000 | K11: ⏳ En attente | L11: En cours
B12: OW-0006 | C12: 24/05/2026 | D12: Haja Rabe | E12: Port Toamasina | F12: Ambositra | G12: 460 km | H12: Camion 5T | I12: 3685000 | J12: 3685000 | K12: ❌ Refusé | L12: Prix refusé
B13: OW-0007 | C13: 25/05/2026 | D13: Tanà Distribution | E13: Analakely, Tanà | F13: Antsirabe | G13: 167 km | H13: Camionnette | I13: 931000 | J13: 931000 | K13: ⏳ En attente | L13: Devis émis
B14: TOTAL (devis acceptés) | I14: =SUMIF(K7:K13,"✅ Accepté",I7:I13) -> 14172000 | J14: =COUNTIF(K7:K13,"✅ Accepté")&" acceptés" -> 4 acceptés
B16: 📈 STATISTIQUES RAPIDES
B17: Devis émis | C17: =COUNTA(B7:B13) -> 7
B18: Devis acceptés | C18: =COUNTIF(K7:K13,"✅ Accepté") -> 4
B19: Taux de conversion | C19: =IFERROR(COUNTIF(K7:K13,"✅ Accepté")/COUNTA(B7:B13),0) -> 0.57142857
B20: CA total (acceptés) | C20: =SUMIF(K7:K13,"✅ Accepté",I7:I13) -> 14172000
B21: Montant moyen / devis | C21: =IFERROR(AVERAGE(I7:I13),0) -> 2736142.9
