Workbook
Name _000: #REF!
Name _000: #REF!
Name _000: #REF!
Name _000: #REF!
Name _000: #REF!
Name _000: #REF!
Name _000: #REF!
Name _000: #REF!
Name _1000: #REF!
Name _1000: #REF!
Name _1000: #REF!
Name _1000: #REF!
Name _1000: #REF!
Name _1000: #REF!
Name _1000: #REF!
Name _1000: #REF!
Name _101: #REF!
Name _101: #REF!
Name _101: #REF!
Name _101: #REF!
Name _101: #REF!
Name _101: #REF!
Name _101: #REF!
Name _101: #REF!
Name _102: #REF!
Name _102: #REF!
Name _102: #REF!
Name _102: #REF!
Name _102: #REF!
Name _102: #REF!
Name _102: #REF!
Name _102: #REF!
Name _103: #REF!
Name _103: #REF!
Name _103: #REF!
Name _103: #REF!
Name _103: #REF!
Name _103: #REF!
Name _103: #REF!
Name _103: #REF!
Name _201: #REF!
Name _201: #REF!
Name _201: #REF!
Name _201: #REF!
Name _201: #REF!
Name _201: #REF!
Name _201: #REF!
Name _201: #REF!
Name _202: #REF!
Name _202: #REF!
Name _202: #REF!
Name _202: #REF!
Name _202: #REF!
Name _202: #REF!
Name _202: #REF!
Name _202: #REF!
Name _202a: #REF!
Name _202a: #REF!
Name _202a: #REF!
Name _202a: #REF!

Sheet DQE REHAB BAT A
B2: TRAVAUX DE REHABILITATION
B3: BATIMENT A (avec extension toilette/douche et cuisine)
A4: N° | B4: DESIGNATIONS | C4: U | D4: QTE ECAE | E4: PU | F4: P.HT
A5: 1 | B5: INSTALLATION ET REPLI DE CHANTIER
A6: 1.1 | B6: Installation et repli de chantier | C6: Fft | D6: 1 | E6: 6000000 | F6: =+D6*E6 -> 6000000
A7: 1.2 | B7: Transport des matériaux | C7: Fft | D7: 1 | E7: 5000000 | F7: =+D7*E7 -> 5000000
B8: TOTAL INSTALLATION ET REPLI DE CHANTIER | F8: =SUM(F6:F7) -> 11000000
A9: 2 | B9: TERRASSEMENT
A10: 2.1 | B10: Evacuations des terres et débris excédentaires | C10: fft | D10: 1 | E10: 500000 | F10: =+D10*E10 -> 500000
A11: 2.2 | B11: Fouille en rigole en terrain meuble jusqu'à 0,50m pour fondation | C11: m3 | D11: 18.5 | E11: 24000 | F11: =+D11*E11 -> 444000
A12: 2.3 | B12: Remblai d'emprunt y compris nivellement, compactage et toutes sujétions. | C12: m3 | D12: =D11/2.2 -> 8.4090909 | E12: 30000 | F12: =+D12*E12 -> 252272.73
A13: TOTAL TERRASSEMENT | F13: =SUM(F10:F12) -> 1196272.7
A14: 3 | B14: OUVRAGES EN INFRASTRUCTURE
A15: 3.1 | B15: Mise en œuvre de béton de propreté dosé à 150 kg de 0,05 m d'épaisseur y compris toutes sujétions. Concerne : Béton de propreté | C15: m3 | D15: 8.78 | E15: 300000 | F15: =E15*D15 -> 2634000
A16: 3.2 | B16: Mise en œuvre de béton dosé à 250 kg ép. 10cm y compris toutes sujétions. Concerne : Béton de forme | C16: m3 | D16: =D15*2 -> 17.56 | E16: 380000 | F16: =+D16*E16 -> 6672800
A17: 3.3 | B17: Mise en œuvre de béton dosé à 350 kg y compris toutes sujétions. | C17: m3 | D17: =4.5-1 -> 3.5 | E17: 600000 | F17: =+D17*E17 -> 2100000
A18: 3.4 | B18: Fourniture et pose des armatures de tous diamètres, y compris coupe, façonnage, ligature et toutes sujétions de mise en œuvre. | C18: kg | D18: =+D17*90 -> 315 | E18: 12000 | F18: =+D18*E18 -> 3780000
A19: 3.5 | B19: Fourniture et pose de coffrage en bois ordinaire du pays, y compris toutes sujétions de mise en œuvre. | C19: m2 | D19: =+D17*14.2 -> 49.7 | E19: 25000 | F19: =+D19*E19 -> 1242500
A20: 3.6 | B20: Mise en œuvre hérissonne y compris toutes sujétions de mise en œuvre. Concerne : Dallage | C20: m3 | D20: 28.52 | E20: 110000 | F20: =+D20*E20 -> 3137200
A21: 3.7 | B21: Mise en œuvre de maçonnerie de moellon y compris toutes sujétions de mise en œuvre. Concerne : Fondation | C21: m3 | D21: 4.96 | E21: 480000 | F21: =+D21*E21 -> 2380800
A22: 3.8 | B22: Mise en œuvre de chape d'ép 4cm bouchardée au mortier dosée 400 kg, y compris toutes sujétions de mise en œuvre. Concerne : Dallage | C22: m² | D22: 182.5 | E22: 25000 | F22: =+D22*E22 -> 4562500
B23: TOTAL OUVRAGES EN INFRASTRUCTURE | F23: =SUM(F15:F22) -> 26509800
A24: 4 | B24: OUVRAGES EN SUPERSTRUCTURE
A25: 4.1 | B25: Mise en œuvre de béton dosé à 350 kg y compris toutes sujétions. | C25: m3 | D25: 16 | E25: 600000 | F25: =+D25*E25 -> 9600000
A26: 4.2 | B26: Fourniture et pose des armatures de tous diamètres, y compris coupe, façonnage, ligature et toutes sujétions de mise en œuvre. | C26: kg | D26: =+D25*90 -> 1440 | E26: 12000 | F26: =+D26*E26 -> 17280000
A27: 4.3 | B27: Fourniture et pose de coffrage en bois ordinaire du pays, y compris toutes sujétions de mise en œuvre. | C27: m2 | D27: =+D25*14.2 -> 227.2 | E27: 25000 | F27: =+D27*E27 -> 5680000
A28: TOTAL OUVRAGES EN SUPERSTRUCTURE | F28: =SUM(F25:F27) -> 32560000
A29: 5 | B29: CHARPENTE - COUVERTURE - PLAFONNAGE
A30: 5.1 | B30: Fourniture et pose de couverture en TOG 50/100ème y compris toutes sujétions. Concerne : Toiture | C30: m2 | D30: =142.96*1.2 -> 171.552 | E30: 43513.587 | F30: =+D30*E30 -> 7464842.9
A31: 5.2 | B31: Fourniture et pose de tissus thermo réflecteur sous toiture y compris fourure placo F53 pour tendeur et couvre joint du film Concerne : Toiture | C31: m2 | D31: =+D30 -> 171.552 | E31: 28451.191 | F31: =+D31*E31 -> 4880858.8
A32: 5.3 | B32: Fourniture et pose de charpentes métalliques en panne C 100 y compris toutes sujétions de mise en œuvre | C32: ml | D32: =148.8*1.2 -> 178.56 | E32: 38492.788 | F32: =+D32*E32 -> 6873272.3
A33: 5.4 | B33: Fourniture et pose DEP diam100 | C33: ml | D33: 16 | E33: 87863.973 | F33: =+D33*E33 -> 1405823.6
A34: TOTAL CHARPENTE - COUVERTURE - PLAFONNAGE | F34: =SUM(F30:F33) -> 20624798
A35: 6 | B35: MACONNERIES ET RAVALEMENT
A36: 6.1 | B36: Mise en œuvres de maçonnerie de PARPAING D15 hourdés au mortier dosé à 300kg, y compris toutes sujétions. | C36: m2 | D36: =D37*0.25+100 -> 191.1875 | E36: 50000 | F36: =+D36*E36 -> 9559375
A37: 6.2 | B37: Mise en œuvre d'enduit dosé au mortier dosé à 350 kg y compris toutes sujétions Concerne : Ravalement | C37: m2 | D37: 364.75 | E37: 25000 | F37: =+D37*E37 -> 9118750
A38: 6.3 | B38: Mise en œuvre d'un enduit décoratif au mortier, rainuré et tracé régulièrement en appareillage de briques, avec peinture de finition adaptée, y compris préparation du support et toutes sujétions. | C38: m2 | D38: =D43*0.3 -> 95.655 | E38: 10000 | F38: =D38*E38 -> 956550
B39: TOTAL MACONNERIES ET RAVALEMENT | F39: =SUM(F36:F38) -> 19634675
A40: 7 | B40: PEINTURE
A41: 7.1 | B41: Enduit de peintre beissier | C41: m2 | D41: =D42 -> 348.5625 | E41: 9000 | F41: =+D41*E41 -> 3137062.5
...

Sheet DQE REHAB BAT B
B2: TRAVAUX DE REHABILITATION
B3: BATIMENT B
A4: N° | B4: DESIGNATIONS | C4: U | D4: QTE ECAE | E4: PU | F4: P.HT
A5: 1 | B5: INSTALLATION ET REPLI DE CHANTIER
A6: 1.1 | B6: Installation et repli de chantier | C6: Fft | D6: 0 | E6: 6000000 | F6: =+D6*E6 -> 0
A7: 1.2 | B7: Transport des matériaux | C7: Fft | D7: 0 | E7: 7000000 | F7: =+D7*E7 -> 0
B8: TOTAL INSTALLATION ET REPLI DE CHANTIER | F8: =SUM(F6:F7) -> 0
A9: 2 | B9: TERRASSEMENT
A10: 2.1 | B10: Evacuations des terres et débris excédentaires | C10: fft | D10: 1 | E10: 200000 | F10: =+D10*E10 -> 200000
A11: 2.2 | B11: Fouille en rigole en terrain meuble jusqu'à 0,50m pour fondation | C11: m3 | D11: 16 | E11: 24000 | F11: =+D11*E11 -> 384000
A12: 2.3 | B12: Remblai d'emprunt y compris nivellement, compactage et toutes sujétions. | C12: m3 | D12: =D11/2.2 -> 7.2727273 | E12: 30000 | F12: =+D12*E12 -> 218181.82
A13: TOTAL TERRASSEMENT | F13: =SUM(F10:F12) -> 802181.82
A14: 3 | B14: OUVRAGES EN INFRASTRUCTURE
A15: 3.1 | B15: Mise en œuvre de béton de propreté dosé à 150 kg de 0,05 m d'épaisseur y compris toutes sujétions. Concerne : Béton de propreté | C15: m3 | D15: 2.72 | E15: 300000 | F15: =E15*D15 -> 816000
A16: 3.2 | B16: Mise en œuvre de béton dosé à 250 kg ép. 10cm y compris toutes sujétions. Concerne : Béton de forme | C16: m3 | D16: =D15*2 -> 5.44 | E16: 380000 | F16: =+D16*E16 -> 2067200
A17: 3.3 | B17: Mise en œuvre de béton dosé à 350 kg y compris toutes sujétions. | C17: m3 | D17: 1.5 | E17: 600000 | F17: =+D17*E17 -> 900000
A18: 3.4 | B18: Fourniture et pose des armatures de tous diamètres, y compris coupe, façonnage, ligature et toutes sujétions de mise en œuvre. | C18: kg | D18: =D17*90 -> 135 | E18: 12000 | F18: =+D18*E18 -> 1620000
A19: 3.5 | B19: Fourniture et pose de coffrage en bois ordinaire du pays, y compris toutes sujétions de mise en œuvre. | C19: m2 | D19: =D17*14.2 -> 21.3 | E19: 25000 | F19: =+D19*E19 -> 532500
A20: 3.6 | B20: Mise en œuvre hérissonne y compris toutes sujétions de mise en œuvre. Concerne : Dallage | C20: m3 | D20: 8.15 | E20: 110000 | F20: =+D20*E20 -> 896500
A21: 3.7 | B21: Mise en œuvre de maçonnerie de moellon y compris toutes sujétions de mise en œuvre. Concerne : Fondation | C21: m3 | D21: 1.78 | E21: 480000 | F21: =+D21*E21 -> 854400
A22: 3.8 | B22: Mise en œuvre de chape d'ép 4cm bouchardée au mortier dosée 400 kg, y compris toutes sujétions de mise en œuvre. Concerne : Dallage | C22: m² | D22: 56.88 | E22: 25000 | F22: =+D22*E22 -> 1422000
B23: TOTAL OUVRAGES EN INFRASTRUCTURE | F23: =SUM(F15:F22) -> 9108600
A24: 4 | B24: OUVRAGES EN SUPERSTRUCTURE
A25: 4.1 | B25: Mise en œuvre de béton dosé à 350 kg y compris toutes sujétions. | C25: m3 | D25: =8.92 -> 8.92 | E25: 600000 | F25: =+D25*E25 -> 5352000
A26: 4.2 | B26: Fourniture et pose des armatures de tous diamètres, y compris coupe, façonnage, ligature et toutes sujétions de mise en œuvre. | C26: kg | D26: =D25*90 -> 802.8 | E26: 12000 | F26: =+D26*E26 -> 9633600
A27: 4.3 | B27: Fourniture et pose de coffrage en bois ordinaire du pays, y compris toutes sujétions de mise en œuvre. | C27: m2 | D27: =D25*14.2 -> 126.664 | E27: 25000 | F27: =+D27*E27 -> 3166600
A28: TOTAL OUVRAGES EN SUPERSTRUCTURE | F28: =SUM(F25:F27) -> 18152200
A29: 5 | B29: CHARPENTE - COUVERTURE - PLAFONNAGE
A30: 5.1 | B30: Fourniture et pose de couverture en TOG 50/100ème y compris toutes sujétions. Concerne : Toiture | C30: m2 | D30: 30.23 | E30: 43513.587 | F30: =+D30*E30 -> 1315415.7
A31: 5.2 | B31: Fourniture et pose de tissus thermo réflecteur sous toiture y compris fourure placo F53 pour tendeur et couvre joint du film Concerne : Toiture | C31: m2 | D31: 30.23 | E31: 28451.191 | F31: =+D31*E31 -> 860079.52
A32: 5.3 | B32: Fourniture et pose de charpentes métalliques en panne C 100 y compris toutes sujétions de mise en œuvre | C32: ml | D32: 38.4 | E32: 38492.788 | F32: =+D32*E32 -> 1478123.1
A33: 5.4 | B33: Fourniture et pose DEP diam100 | C33: ml | D33: 10.4 | E33: 87863.973 | F33: =+D33*E33 -> 913785.32
A34: TOTAL CHARPENTE - COUVERTURE - PLAFONNAGE | F34: =SUM(F30:F33) -> 4567403.6
A35: 6 | B35: MACONNERIES ET RAVALEMENT
A36: 6.1 | B36: Mise en œuvres de maçonnerie de PARPAING D15 hourdés au mortier dosé à 300kg, y compris toutes sujétions. | C36: m2 | D36: 22.56 | E36: 50000 | F36: =+D36*E36 -> 1128000
A37: 6.2 | B37: Mise en œuvre d'enduit dosé au mortier dosé à 350 kg y compris toutes sujétions Concerne : Ravalement | C37: m2 | D37: 181.63 | E37: 25000 | F37: =+D37*E37 -> 4540750
A38: 6.3 | B38: Mise en œuvre d'un enduit décoratif au mortier, rainuré et tracé régulièrement en appareillage de briques, avec peinture de finition adaptée, y compris préparation du support et toutes sujétions. | C38: m2 | D38: =D43*0.3 -> 27.2445 | E38: 10000 | F38: =D38*E38 -> 272445
B39: TOTAL MACONNERIES ET RAVALEMENT | F39: =SUM(F36:F38) -> 5941195
A40: 7 | B40: PEINTURE
A41: 7.1 | B41: Enduit de peintre bessier | C41: m2 | D41: =D42 -> 108.978 | E41: 9000 | F41: =+D41*E41 -> 980802
...

Sheet DQE REHAB BAT C
B2: TRAVAUX DE REHABILITATION
B3: BATIMENT C
A4: N° | B4: DESIGNATIONS | C4: U | D4: QTE ECAE | E4: PU | F4: P.HT
A5: 1 | B5: INSTALLATION ET REPLI DE CHANTIER
A6: 1.1 | B6: Installation et repli de chantier | C6: Fft | D6: 0 | E6: 6000000 | F6: =+D6*E6 -> 0
A7: 1.2 | B7: Transport des matériaux | C7: Fft | D7: 0 | E7: 7000000 | F7: =+D7*E7 -> 0
B8: TOTAL INSTALLATION ET REPLI DE CHANTIER | F8: =SUM(F6:F7) -> 0
A9: 2 | B9: TERRASSEMENT
A10: 2.1 | B10: Evacuations des terres et débris excédentaires | C10: fft | D10: 1 | E10: 200000 | F10: =+D10*E10 -> 200000
A11: 2.2 | B11: Fouille en rigole en terrain meuble jusqu'à 0,50m pour fondation | C11: m3 | D11: 16 | E11: 24000 | F11: =+D11*E11 -> 384000
A12: 2.3 | B12: Remblai d'emprunt y compris nivellement, compactage et toutes sujétions. | C12: m3 | D12: =D11/2.2 -> 7.2727273 | E12: 30000 | F12: =+D12*E12 -> 218181.82
A13: TOTAL TERRASSEMENT | F13: =SUM(F10:F12) -> 802181.82
A14: 3 | B14: OUVRAGES EN INFRASTRUCTURE
A15: 3.1 | B15: Mise en œuvre de béton de propreté dosé à 150 kg de 0,05 m d'épaisseur y compris toutes sujétions. Concerne : Béton de propreté | C15: m3 | D15: 2.72 | E15: 300000 | F15: =E15*D15 -> 816000
A16: 3.2 | B16: Mise en œuvre de béton dosé à 250 kg ép. 10cm y compris toutes sujétions. Concerne : Béton de forme | C16: m3 | D16: =D15*2 -> 5.44 | E16: 380000 | F16: =+D16*E16 -> 2067200
A17: 3.3 | B17: Mise en œuvre de béton dosé à 350 kg y compris toutes sujétions. | C17: m3 | D17: 1.5 | E17: 600000 | F17: =+D17*E17 -> 900000
A18: 3.4 | B18: Fourniture et pose des armatures de tous diamètres, y compris coupe, façonnage, ligature et toutes sujétions de mise en œuvre. | C18: kg | D18: =D17*90 -> 135 | E18: 12000 | F18: =+D18*E18 -> 1620000
A19: 3.5 | B19: Fourniture et pose de coffrage en bois ordinaire du pays, y compris toutes sujétions de mise en œuvre. | C19: m2 | D19: =D17*14.2 -> 21.3 | E19: 25000 | F19: =+D19*E19 -> 532500
A20: 3.6 | B20: Mise en œuvre hérissonne y compris toutes sujétions de mise en œuvre. Concerne : Dallage | C20: m3 | D20: 8.15 | E20: 110000 | F20: =+D20*E20 -> 896500
A21: 3.7 | B21: Mise en œuvre de maçonnerie de moellon y compris toutes sujétions de mise en œuvre. Concerne : Fondation | C21: m3 | D21: 1.78 | E21: 480000 | F21: =+D21*E21 -> 854400
A22: 3.8 | B22: Mise en œuvre de chape d'ép 4cm bouchardée au mortier dosée 400 kg, y compris toutes sujétions de mise en œuvre. Concerne : Dallage | C22: m² | D22: 56.88 | E22: 25000 | F22: =+D22*E22 -> 1422000
B23: TOTAL OUVRAGES EN INFRASTRUCTURE | F23: =SUM(F15:F22) -> 9108600
A24: 4 | B24: OUVRAGES EN SUPERSTRUCTURE
A25: 4.1 | B25: Mise en œuvre de béton dosé à 350 kg y compris toutes sujétions. | C25: m3 | D25: =8.92 -> 8.92 | E25: 600000 | F25: =+D25*E25 -> 5352000
A26: 4.2 | B26: Fourniture et pose des armatures de tous diamètres, y compris coupe, façonnage, ligature et toutes sujétions de mise en œuvre. | C26: kg | D26: =D25*90 -> 802.8 | E26: 12000 | F26: =+D26*E26 -> 9633600
A27: 4.3 | B27: Fourniture et pose de coffrage en bois ordinaire du pays, y compris toutes sujétions de mise en œuvre. | C27: m2 | D27: =D25*14.2 -> 126.664 | E27: 25000 | F27: =+D27*E27 -> 3166600
A28: TOTAL OUVRAGES EN SUPERSTRUCTURE | F28: =SUM(F25:F27) -> 18152200
A29: 5 | B29: CHARPENTE - COUVERTURE - PLAFONNAGE
A30: 5.1 | B30: Fourniture et pose de couverture en TOG 50/100ème y compris toutes sujétions. Concerne : Toiture | C30: m2 | D30: 30.23 | E30: 43513.587 | F30: =+D30*E30 -> 1315415.7
A31: 5.2 | B31: Fourniture et pose de tissus thermo réflecteur sous toiture y compris fourure placo F53 pour tendeur et couvre joint du film Concerne : Toiture | C31: m2 | D31: 30.23 | E31: 28451.191 | F31: =+D31*E31 -> 860079.52
A32: 5.3 | B32: Fourniture et pose de charpentes métalliques en panne C 100 y compris toutes sujétions de mise en œuvre | C32: ml | D32: 38.4 | E32: 38492.788 | F32: =+D32*E32 -> 1478123.1
A33: 5.4 | B33: Fourniture et pose DEP diam100 | C33: ml | D33: 10.4 | E33: 87863.973 | F33: =+D33*E33 -> 913785.32
A34: TOTAL CHARPENTE - COUVERTURE - PLAFONNAGE | F34: =SUM(F30:F33) -> 4567403.6
A35: 6 | B35: MACONNERIES ET RAVALEMENT
A36: 6.1 | B36: Mise en œuvres de maçonnerie de PARPAING D15 hourdés au mortier dosé à 300kg, y compris toutes sujétions. | C36: m2 | D36: 22.56 | E36: 50000 | F36: =+D36*E36 -> 1128000
A37: 6.2 | B37: Mise en œuvre d'enduit dosé au mortier dosé à 350 kg y compris toutes sujétions Concerne : Ravalement | C37: m2 | D37: 181.63 | E37: 25000 | F37: =+D37*E37 -> 4540750
A38: 6.3 | B38: Mise en œuvre d'un enduit décoratif au mortier, rainuré et tracé régulièrement en appareillage de briques, avec peinture de finition adaptée, y compris préparation du support et toutes sujétions. | C38: m2 | D38: =D43*0.3 -> 27.2445 | E38: 10000 | F38: =D38*E38 -> 272445
B39: TOTAL MACONNERIES ET RAVALEMENT | F39: =SUM(F36:F38) -> 5941195
A40: 7 | B40: PEINTURE
A41: 7.1 | B41: Enduit de peintre bessier | C41: m2 | D41: =D42 -> 108.978 | E41: 9000 | F41: =+D41*E41 -> 980802
...

Sheet DQE REHAB BLOC SANITAIRE
B2: TRAVAUX DE REHABILITATION
B3: BLOC SANITAIRE A 6 COMPARTIMENTS
A4: N° | B4: DESIGNATIONS | C4: U | D4: QTE ECAE | E4: PU | F4: P.HT
A5: 1 | B5: INSTALLATION ET REPLI DE CHANTIER
A6: 1.1 | B6: Installation et repli de chantier | C6: Fft | D6: 0 | E6: 6000000 | F6: =+D6*E6 -> 0
A7: 1.2 | B7: Transport des matériaux | C7: Fft | D7: 0 | E7: 7000000 | F7: =+D7*E7 -> 0
B8: TOTAL INSTALLATION ET REPLI DE CHANTIER | F8: =SUM(F6:F7) -> 0
A9: 2 | B9: TERRASSEMENT
A10: 2.1 | B10: Débroussaillage, évacuations des terres et débris excédentaires | C10: fft | D10: 1 | E10: 200000 | F10: =E10*D10 -> 200000
A11: TOTAL TERRASSEMENT | F11: =SUM(F10) -> 200000
A12: 3 | B12: OUVRAGES EN INFRASTRUCTURE
A13: 3.1 | B13: Mise en œuvre de béton de propreté dosé à 150 kg de 0,05 m d'épaisseur y compris toutes sujétions. Concerne : Béton de propreté | C13: m3 | D13: 0.61 | E13: 300000 | F13: =E13*D13 -> 183000
A14: 3.2 | B14: Mise en œuvre de béton dosé à 250 kg ép. 8cm y compris toutes sujétions. Concerne : Béton de forme | C14: m3 | D14: 0.916 | E14: 380000 | F14: =+D14*E14 -> 348080
A15: 3.6 | B15: Mise en œuvre hérissonne y compris toutes sujétions de mise en œuvre. Concerne : Dallage | C15: m3 | D15: 1.63 | E15: 110000 | F15: =+D15*E15 -> 179300
A16: 3.8 | B16: Mise en œuvre de chape d'ép 4cm bouchardée au mortier dosée 400 kg, y compris toutes sujétions de mise en œuvre. Concerne : Dallage | C16: m² | D16: 11.2 | E16: 25000 | F16: =+D16*E16 -> 280000
B17: TOTAL OUVRAGES EN INFRASTRUCTURE | F17: =SUM(F13:F16) -> 990380
A18: 4 | B18: OUVRAGES EN SUPERSTRUCTURE
A19: 4.1 | B19: Mise en œuvre de béton dosé à 350 kg y compris toutes sujétions. | C19: m3 | D19: 0.8 | E19: 600000 | F19: =+D19*E19 -> 480000
A20: 4.2 | B20: Fourniture et pose des armatures de tous diamètres, y compris coupe, façonnage, ligature et toutes sujétions de mise en œuvre. | C20: kg | D20: =D19*90 -> 72 | E20: 12000 | F20: =+D20*E20 -> 864000
A21: 4.3 | B21: Fourniture et pose de coffrage en bois ordinaire du pays, y compris toutes sujétions de mise en œuvre. | C21: m2 | D21: =D19*14.2 -> 11.36 | E21: 25000 | F21: =+D21*E21 -> 284000
A22: TOTAL OUVRAGES EN SUPERSTRUCTURE | F22: =SUM(F19:F21) -> 1628000
A23: 5 | B23: CHARPENTE - COUVERTURE - PLAFONNAGE
A24: 5.1 | B24: Fourniture et pose de couverture en TOG 50/100ème y compris toutes sujétions. Concerne : Toiture | C24: m2 | D24: 10.29 | E24: 43513.587 | F24: =+D24*E24 -> 447754.81
A25: 5.2 | B25: Fourniture et pose de tissus thermo réflecteur sous toiture y compris fourure placo F53 pour tendeur et couvre joint du film Concerne : Toiture | C25: m2 | D25: 10.29 | E25: 28451.191 | F25: =+D25*E25 -> 292762.76
A26: 5.3 | B26: Fourniture et pose de charpentes métalliques en panne C 100 y compris toutes sujétions de mise en œuvre | C26: ml | D26: 16 | E26: 38492.788 | F26: =+D26*E26 -> 615884.61
A27: 5.3 | B27: Fourniture et pose de gouttiere en PVC | C27: ml | D27: 8 | E27: 25000 | F27: =+D27*E27 -> 200000
A28: 5.4 | B28: Fourniture et pose DEP diam100 | C28: ml | D28: 8 | E28: 87863.973 | F28: =E28*D28 -> 702911.79
A29: TOTAL CHARPENTE - COUVERTURE - PLAFONNAGE | F29: =SUM(F28:F28) -> 702911.79
A30: 6 | B30: MACONNERIES ET RAVALEMENT
A31: 6.1 | B31: Mise en œuvres de maçonnerie de BRIQUE D15 hourdés au mortier dosé à 300kg, y compris toutes sujétions. | C31: m2 | D31: 7.64 | E31: 50000 | F31: =+D31*E31 -> 382000
A32: 6.2 | B32: Mise en œuvre d'enduit dosé au mortier dosé à 350 kg y compris toutes sujétions Concerne : Ravalement | C32: m2 | D32: 95.08 | E32: 25000 | F32: =+D32*E32 -> 2377000
A33: 6.3 | B33: Mise en œuvre d'un enduit décoratif au mortier, rainuré et tracé régulièrement en appareillage de briques, avec peinture de finition adaptée, y compris préparation du support et toutes sujétions. | C33: m2 | D33: =D38*0.3 -> 3.36 | E33: 10000 | F33: =D33*E33 -> 33600
B34: TOTAL MACONNERIES ET RAVALEMENT | F34: =SUM(F31:F33) -> 2792600
A35: 7 | B35: PEINTURE
A36: 7.1 | B36: Enduit de peintre bessier | C36: m2 | D36: =D37 -> 57.048 | E36: 9000 | F36: =+D36*E36 -> 513432
A37: 7.2 | B37: Peinture acrylique intérieure en deux couches | C37: m2 | D37: =D32*0.6 -> 57.048 | E37: 8000 | F37: =+D37*E37 -> 456384
A38: 7.3 | B38: Peinture acrylique extérieure en deux couches | C38: m2 | D38: =D16 -> 11.2 | E38: 8000 | F38: =+D38*E38 -> 89600
A39: 7.5 | B39: Peinture sol | C39: m2 | D39: =D16 -> 11.2 | E39: 15000 | F39: =D39*E39 -> 168000
A40: 7.4 | B40: Peinture glycérophtalique en deux couches | C40: m2 | D40: 19.53 | E40: 15000 | F40: =+D40*E40 -> 292950
A41: TOTAL PEINTURE | F41: =SUM(F36:F40) -> 1520366
...

Sheet DQE LOCAL TECH
B2: TRAVAUX DE REHABILITATION
B3: LOCAL TECHNIQUE ET ELECTRIFICATION GENERALE DE LA ZONE
B4: DESIGNATIONS | C4: U | D4: QTE ECAE | E4: PU | F4: P.HT
A5: 1 | B5: MENUISERIE ET VITRERIES
A6: 1.1 | B6: Porte métallique pleine dim. 0,9x2m | C6: u | D6: 1 | E6: 900000 | F6: =SUM(D6*E6) -> 900000
A7: 1.2 | B7: Fourniture et pose de grille de protection | C7: u | D7: 1 | E7: 600000 | F7: =SUM(D7*E7) -> 600000
A8: TOTAL MENUISERIE ET VITRERIES | F8: =SUM(F6:F7) -> 1500000
A9: 2 | B9: ELECTRICITE
A10: 2.1 | B10: Tableau divisionnaire TD équipé de disjoncteur | C10: U | D10: 1 | E10: 800000 | F10: =+D10*E10 -> 800000
A11: 2.2 | B11: Câble électrique rigide RO2V 4mm² | C11: ml | D11: 150 | E11: 15000 | F11: =+E11*D11 -> 2250000
A12: 2.3 | B12: Gaine annelée rouge TPC - Ø 40mm | C12: ml | D12: 150 | E12: 10000 | F12: =+E12*D12 -> 1500000
A13: TOTAL ELECTRICITE | F13: =SUM(F10:F12) -> 4550000
C14: TOTAL HT | F14: =SUM(F8+F13) -> 6050000
A16: Arrêté le présent devis à la somme de: "Six millions cinquante mille Ariary"
F18: Le Soummisssionnaire

Sheet DQE NOUV CONSTRUCTION
B2: TRAVAUX DE CONSTRUCTION
B3: NOUVELLE CONSTRUCTION (près du château d’eau)
A4: N° | B4: DESIGNATIONS | C4: U | D4: QTE ECAE | E4: PU | F4: P.HT
A5: 1 | B5: INSTALLATION ET REPLI DE CHANTIER
A6: 1.1 | B6: Installation et repli de chantier | C6: Fft | D6: 0 | E6: 6000000 | F6: =+D6*E6 -> 0
A7: 1.2 | B7: Transport des matériaux | C7: Fft | D7: 0 | E7: 7000000 | F7: =+D7*E7 -> 0
B8: TOTAL INSTALLATION ET REPLI DE CHANTIER | F8: =SUM(F6:F7) -> 0
A9: 2 | B9: TERRASSEMENT
A10: 2.1 | B10: Fouille en rigole en terrain meuble jusqu'à 0,50m pour fondation | C10: m3 | D10: 16 | E10: 24000 | F10: =+D10*E10 -> 384000
A11: 2.2 | B11: Remblai d'emprunt y compris nivellement, compactage et toutes sujétions. | C11: m3 | D11: =D10/2.2 -> 7.2727273 | E11: 30000 | F11: =+D11*E11 -> 218181.82
A12: TOTAL TERRASSEMENT | F12: =SUM(F10:F11) -> 602181.82
A13: 3 | B13: OUVRAGES EN INFRASTRUCTURE
A14: 3.1 | B14: Mise en œuvre de béton de propreté dosé à 150 kg de 0,05 m d'épaisseur y compris toutes sujétions. Concerne : Béton de propreté | C14: m3 | D14: 2.92 | E14: 300000 | F14: =E14*D14 -> 876000
A15: 3.2 | B15: Mise en œuvre de béton dosé à 250 kg ép. 10cm y compris toutes sujétions. Concerne : Béton de forme | C15: m3 | D15: =D14*2 -> 5.84 | E15: 380000 | F15: =+D15*E15 -> 2219200
A16: 3.3 | B16: Mise en œuvre de béton dosé à 350 kg y compris toutes sujétions. | C16: m3 | D16: 2.36 | E16: 600000 | F16: =+D16*E16 -> 1416000
A17: 3.4 | B17: Fourniture et pose des armatures de tous diamètres, y compris coupe, façonnage, ligature et toutes sujétions de mise en œuvre. | C17: kg | D17: =D16*90 -> 212.4 | E17: 12000 | F17: =+D17*E17 -> 2548800
A18: 3.5 | B18: Fourniture et pose de coffrage en bois ordinaire du pays, y compris toutes sujétions de mise en œuvre. | C18: m2 | D18: =D16*14.2 -> 33.512 | E18: 25000 | F18: =+D18*E18 -> 837800
A19: 3.6 | B19: Mise en œuvre hérissonne y compris toutes sujétions de mise en œuvre. Concerne : Dallage | C19: m3 | D19: 8.465 | E19: 110000 | F19: =+D19*E19 -> 931150
A20: 3.7 | B20: Mise en œuvre de maçonnerie de moellon y compris toutes sujétions de mise en œuvre. Concerne : Fondation | C20: m3 | D20: 3.31 | E20: 480000 | F20: =+D20*E20 -> 1588800
A21: 3.8 | B21: Mise en œuvre de chape d'ép 4cm bouchardée au mortier dosée 400 kg, y compris toutes sujétions de mise en œuvre. Concerne : Dallage | C21: m² | D21: 58.6 | E21: 0 | F21: =+D21*E21 -> 0
B22: TOTAL OUVRAGES EN INFRASTRUCTURE | F22: =SUM(F14:F21) -> 10417750
A23: 4 | B23: OUVRAGES EN SUPERSTRUCTURE
A24: 4.1 | B24: Mise en œuvre de béton dosé à 350 kg y compris toutes sujétions. | C24: m3 | D24: =9.87+2 -> 11.87 | E24: 600000 | F24: =+D24*E24 -> 7122000
A25: 4.2 | B25: Fourniture et pose des armatures de tous diamètres, y compris coupe, façonnage, ligature et toutes sujétions de mise en œuvre. | C25: kg | D25: =D24*90 -> 1068.3 | E25: 12000 | F25: =+D25*E25 -> 12819600
A26: 4.3 | B26: Fourniture et pose de coffrage en bois ordinaire du pays, y compris toutes sujétions de mise en œuvre. | C26: m2 | D26: =D24*14.2 -> 168.554 | E26: 25000 | F26: =+D26*E26 -> 4213850
A27: TOTAL OUVRAGES EN SUPERSTRUCTURE | F27: =SUM(F24:F26) -> 24155450
A28: 5 | B28: CHARPENTE - COUVERTURE - PLAFONNAGE
A29: 5.1 | B29: Fourniture et pose de couverture en TOG 50/100ème y compris toutes sujétions. Concerne : Toiture | C29: m2 | D29: 32.56 | E29: 43513.587 | F29: =+D29*E29 -> 1416802.4
A30: 5.2 | B30: Fourniture et pose de tissus thermo réflecteur sous toiture y compris fourure placo F53 pour tendeur et couvre joint du film Concerne : Toiture | C30: m2 | D30: 32.56 | E30: 28451.191 | F30: =+D30*E30 -> 926370.79
A31: 5.3 | B31: Fourniture et pose de charpentes métalliques en panne C 100 y compris toutes sujétions de mise en œuvre | C31: ml | D31: 38.4 | E31: 38492.788 | F31: =+D31*E31 -> 1478123.1
A32: 5.4 | B32: Fourniture et pose DEP diam100 | C32: ml | D32: 10.4 | E32: 87863.973 | F32: =+D32*E32 -> 913785.32
A33: TOTAL CHARPENTE - COUVERTURE - PLAFONNAGE | F33: =SUM(F29:F32) -> 4735081.6
A34: 6 | B34: MACONNERIES ET RAVALEMENT
A35: 6.1 | B35: Mise en œuvres de maçonnerie de PARPAING D15 hourdés au mortier dosé à 300kg, y compris toutes sujétions. | C35: m2 | D35: 82.56 | E35: 50000 | F35: =+D35*E35 -> 4128000
A36: 6.2 | B36: Mise en œuvre d'enduit dosé au mortier dosé à 350 kg y compris toutes sujétions Concerne : Ravalement | C36: m2 | D36: =D35*2.2 -> 181.632 | E36: 25000 | F36: =+D36*E36 -> 4540800
A37: 6.3 | B37: Mise en œuvre d'un enduit décoratif au mortier, rainuré et tracé régulièrement en appareillage de briques, avec peinture de finition adaptée, y compris préparation du support et toutes sujétions. | C37: m2 | D37: =D42*0.3 -> 17.58 | E37: 10000 | F37: =D37*E37 -> 175800
B38: TOTAL MACONNERIES ET RAVALEMENT | F38: =SUM(F35:F37) -> 8844600
A39: 7 | B39: PEINTURE
A40: 7.1 | B40: Enduit de peintre bessier | C40: m2 | D40: =D41 -> 108.9792 | E40: 9000 | F40: =+D40*E40 -> 980812.8
A41: 7.2 | B41: Peinture acrylique intérieure en deux couches | C41: m2 | D41: =D36*0.6 -> 108.9792 | E41: 8000 | F41: =+D41*E41 -> 871833.6
...

Sheet RECAP
A2: RECAPITULATIF DES TRAVAUX DE REHABILITATION ET DE CONSTRUCTION A MANGATSA
A3: N° | B3: DESIGNATION | C3: NOMBRE | D3: PRIX UNITAIRE | E3: MONTANT
A4: 1 | B4: BATIMENT A (avec extension toilette/douche et cuisine) | C4: 1 | D4: =+'DQE REHAB BAT A'!C85 -> 1.5151241e+08 | E4: =C4*D4 -> 1.5151241e+08
A5: =A4+1 -> 2 | B5: BATIMENT B | C5: 1 | D5: ='DQE REHAB BAT B'!F62 -> 51975926 | E5: =+D5*C5 -> 51975926
A6: =A5+1 -> 3 | B6: BATIMENT C | C6: 1 | D6: ='DQE REHAB BAT C'!F62 -> 51975926 | E6: =+D6*C6 -> 51975926
A7: =A6+1 -> 4 | B7: BLOC SANITAIRE | C7: 1 | D7: ='DQE REHAB BLOC SANITAIRE'!F62 -> 24663008 | E7: =+D7*C7 -> 24663008
A8: =A7+1 -> 5 | B8: LOCAL TECHNIQUE ET ELECTRIFICATION | C8: 1 | D8: ='DQE LOCAL TECH'!F14 -> 6050000 | E8: =+D8*C8 -> 6050000
A9: =A8+1 -> 6 | B9: NOUVELLE CONSTRUCTION | C9: 1 | D9: ='DQE NOUV CONSTRUCTION'!F61 -> 60947510 | E9: =+D9*C9 -> 60947510
A10: TOTAL EN ARIARY TTC | E10: =SUM(E4:E9) -> 3.4712478e+08
A12: Arrêté le présent devis à la somme de: "Trois cent quarante sept millions cent vingt quatre mille sept cent soixante dix huit Ariary"
E14: Le Responsable
